<mujoco>
	<worldbody>
        <light diffuse=".5 .5 .5" pos="0 0 3" dir="0 0 -1"/>
		<geom type="plane" size="10 10 0.1" rgba=".9 0 0 1"/>

		<body name="rotate" pos="0 0 .3">
			<joint type="free"/>
			<geom type="box" size="0.3 0.05 0.05" rgba="1 1 0 1"/>
			
			<body pos="0.2 0.1 -0.05">
				<joint name="arm1" type="hinge" axis="0 1 0"/>
				<geom type="cylinder" size="0.05 0.07" rgba="1 0 1 1"/>
			</body>
			<body pos="0.2 -0.1 -0.05">
				<joint name="arm2" type="hinge" axis="0 1 0"/>
				<geom type="cylinder" size="0.05 0.07" rgba="1 0 1 1"/>
			</body>
			<body pos="-0.3 0 0">
				<joint name="leg" type="hinge" axis="0 1 0"/>
				<geom type="capsule" size="0.03 0.05" rgba="1 0 1 1"/>
			</body>
		</body>
	</worldbody>

	<actuator>
		<motor joint="arm1" name="arm1"/>
		<motor joint="arm2" name="arm2"/>
		<motor joint="leg" name="leg"/>
	</actuator>
</mujoco>
